Workbook
Name ___________________________________________________________________________________________________________________df1: {#N/A,#N/A,FALSE,"Aging Summary";#N/A,#N/A,FALSE,"Ratio Analysis";#N/A,#N/A,FALSE,"Test 120 Day Accts";#N/A,#N/A,FALSE,"Tickmarks"}
Name _________________________________________________________________________________________________________________df1: {#N/A,#N/A,FALSE,"Aging Summary";#N/A,#N/A,FALSE,"Ratio Analysis";#N/A,#N/A,FALSE,"Test 120 Day Accts";#N/A,#N/A,FALSE,"Tickmarks"}
Name ________________________________________________________________________________________________________________df1: {#N/A,#N/A,FALSE,"Aging Summary";#N/A,#N/A,FALSE,"Ratio Analysis";#N/A,#N/A,FALSE,"Test 120 Day Accts";#N/A,#N/A,FALSE,"Tickmarks"}
Name _______________________________________________________________________________________________________________df1: {#N/A,#N/A,FALSE,"Aging Summary";#N/A,#N/A,FALSE,"Ratio Analysis";#N/A,#N/A,FALSE,"Test 120 Day Accts";#N/A,#N/A,FALSE,"Tickmarks"}
Name _____________________________________________________________________________________________________________df1: {#N/A,#N/A,FALSE,"Aging Summary";#N/A,#N/A,FALSE,"Ratio Analysis";#N/A,#N/A,FALSE,"Test 120 Day Accts";#N/A,#N/A,FALSE,"Tickmarks"}
Name ____________________________________________________________________________________________________________df1: {#N/A,#N/A,FALSE,"Aging Summary";#N/A,#N/A,FALSE,"Ratio Analysis";#N/A,#N/A,FALSE,"Test 120 Day Accts";#N/A,#N/A,FALSE,"Tickmarks"}
Name ___________________________________________________________________________________________________________df1: {#N/A,#N/A,FALSE,"Aging Summary";#N/A,#N/A,FALSE,"Ratio Analysis";#N/A,#N/A,FALSE,"Test 120 Day Accts";#N/A,#N/A,FALSE,"Tickmarks"}
Name _________________________________________________________________________________________________________df1: {#N/A,#N/A,FALSE,"Aging Summary";#N/A,#N/A,FALSE,"Ratio Analysis";#N/A,#N/A,FALSE,"Test 120 Day Accts";#N/A,#N/A,FALSE,"Tickmarks"}
Name ________________________________________________________________________________________________________df1: {#N/A,#N/A,FALSE,"Aging Summary";#N/A,#N/A,FALSE,"Ratio Analysis";#N/A,#N/A,FALSE,"Test 120 Day Accts";#N/A,#N/A,FALSE,"Tickmarks"}
Name _______________________________________________________________________________________________________df1: {#N/A,#N/A,FALSE,"Aging Summary";#N/A,#N/A,FALSE,"Ratio Analysis";#N/A,#N/A,FALSE,"Test 120 Day Accts";#N/A,#N/A,FALSE,"Tickmarks"}
Name ______________________________________________________________________________________________________df1: {#N/A,#N/A,FALSE,"Aging Summary";#N/A,#N/A,FALSE,"Ratio Analysis";#N/A,#N/A,FALSE,"Test 120 Day Accts";#N/A,#N/A,FALSE,"Tickmarks"}
Name _____________________________________________________________________________________________________df1: {#N/A,#N/A,FALSE,"Aging Summary";#N/A,#N/A,FALSE,"Ratio Analysis";#N/A,#N/A,FALSE,"Test 120 Day Accts";#N/A,#N/A,FALSE,"Tickmarks"}
Name ____________________________________________________________________________________________________df1: {#N/A,#N/A,FALSE,"Aging Summary";#N/A,#N/A,FALSE,"Ratio Analysis";#N/A,#N/A,FALSE,"Test 120 Day Accts";#N/A,#N/A,FALSE,"Tickmarks"}
Name __________________________________________________________________________________________________df1: {#N/A,#N/A,FALSE,"Aging Summary";#N/A,#N/A,FALSE,"Ratio Analysis";#N/A,#N/A,FALSE,"Test 120 Day Accts";#N/A,#N/A,FALSE,"Tickmarks"}
Name _________________________________________________________________________________________________df1: {#N/A,#N/A,FALSE,"Aging Summary";#N/A,#N/A,FALSE,"Ratio Analysis";#N/A,#N/A,FALSE,"Test 120 Day Accts";#N/A,#N/A,FALSE,"Tickmarks"}
Name ________________________________________________________________________________________________df1: {#N/A,#N/A,FALSE,"Aging Summary";#N/A,#N/A,FALSE,"Ratio Analysis";#N/A,#N/A,FALSE,"Test 120 Day Accts";#N/A,#N/A,FALSE,"Tickmarks"}
Name _______________________________________________________________________________________________df1: {#N/A,#N/A,FALSE,"Aging Summary";#N/A,#N/A,FALSE,"Ratio Analysis";#N/A,#N/A,FALSE,"Test 120 Day Accts";#N/A,#N/A,FALSE,"Tickmarks"}
Name ______________________________________________________________________________________________df1: {#N/A,#N/A,FALSE,"Aging Summary";#N/A,#N/A,FALSE,"Ratio Analysis";#N/A,#N/A,FALSE,"Test 120 Day Accts";#N/A,#N/A,FALSE,"Tickmarks"}
Name _____________________________________________________________________________________________df1: {#N/A,#N/A,FALSE,"Aging Summary";#N/A,#N/A,FALSE,"Ratio Analysis";#N/A,#N/A,FALSE,"Test 120 Day Accts";#N/A,#N/A,FALSE,"Tickmarks"}
Name ____________________________________________________________________________________________df1: {#N/A,#N/A,FALSE,"Aging Summary";#N/A,#N/A,FALSE,"Ratio Analysis";#N/A,#N/A,FALSE,"Test 120 Day Accts";#N/A,#N/A,FALSE,"Tickmarks"}
Name ___________________________________________________________________________________________df1: {#N/A,#N/A,FALSE,"Aging Summary";#N/A,#N/A,FALSE,"Ratio Analysis";#N/A,#N/A,FALSE,"Test 120 Day Accts";#N/A,#N/A,FALSE,"Tickmarks"}
Name __________________________________________________________________________________________df1: {#N/A,#N/A,FALSE,"Aging Summary";#N/A,#N/A,FALSE,"Ratio Analysis";#N/A,#N/A,FALSE,"Test 120 Day Accts";#N/A,#N/A,FALSE,"Tickmarks"}
Name _________________________________________________________________________________________df1: {#N/A,#N/A,FALSE,"Aging Summary";#N/A,#N/A,FALSE,"Ratio Analysis";#N/A,#N/A,FALSE,"Test 120 Day Accts";#N/A,#N/A,FALSE,"Tickmarks"}
Name ________________________________________________________________________________________df1: {#N/A,#N/A,FALSE,"Aging Summary";#N/A,#N/A,FALSE,"Ratio Analysis";#N/A,#N/A,FALSE,"Test 120 Day Accts";#N/A,#N/A,FALSE,"Tickmarks"}
Name _______________________________________________________________________________________df1: {#N/A,#N/A,FALSE,"Aging Summary";#N/A,#N/A,FALSE,"Ratio Analysis";#N/A,#N/A,FALSE,"Test 120 Day Accts";#N/A,#N/A,FALSE,"Tickmarks"}
Name ______________________________________________________________________________________df1: {#N/A,#N/A,FALSE,"Aging Summary";#N/A,#N/A,FALSE,"Ratio Analysis";#N/A,#N/A,FALSE,"Test 120 Day Accts";#N/A,#N/A,FALSE,"Tickmarks"}
Name _____________________________________________________________________________________df1: {#N/A,#N/A,FALSE,"Aging Summary";#N/A,#N/A,FALSE,"Ratio Analysis";#N/A,#N/A,FALSE,"Test 120 Day Accts";#N/A,#N/A,FALSE,"Tickmarks"}
Name ____________________________________________________________________________________df1: {#N/A,#N/A,FALSE,"Aging Summary";#N/A,#N/A,FALSE,"Ratio Analysis";#N/A,#N/A,FALSE,"Test 120 Day Accts";#N/A,#N/A,FALSE,"Tickmarks"}
Name ___________________________________________________________________________________df1: {#N/A,#N/A,FALSE,"Aging Summary";#N/A,#N/A,FALSE,"Ratio Analysis";#N/A,#N/A,FALSE,"Test 120 Day Accts";#N/A,#N/A,FALSE,"Tickmarks"}
Name __________________________________________________________________________________df1: {#N/A,#N/A,FALSE,"Aging Summary";#N/A,#N/A,FALSE,"Ratio Analysis";#N/A,#N/A,FALSE,"Test 120 Day Accts";#N/A,#N/A,FALSE,"Tickmarks"}
Name _________________________________________________________________________________df1: {#N/A,#N/A,FALSE,"Aging Summary";#N/A,#N/A,FALSE,"Ratio Analysis";#N/A,#N/A,FALSE,"Test 120 Day Accts";#N/A,#N/A,FALSE,"Tickmarks"}
Name ________________________________________________________________________________df1: {#N/A,#N/A,FALSE,"Aging Summary";#N/A,#N/A,FALSE,"Ratio Analysis";#N/A,#N/A,FALSE,"Test 120 Day Accts";#N/A,#N/A,FALSE,"Tickmarks"}
Name ______________________________________________________________________________df1: {#N/A,#N/A,FALSE,"Aging Summary";#N/A,#N/A,FALSE,"Ratio Analysis";#N/A,#N/A,FALSE,"Test 120 Day Accts";#N/A,#N/A,FALSE,"Tickmarks"}
Name _____________________________________________________________________________df1: {#N/A,#N/A,FALSE,"Aging Summary";#N/A,#N/A,FALSE,"Ratio Analysis";#N/A,#N/A,FALSE,"Test 120 Day Accts";#N/A,#N/A,FALSE,"Tickmarks"}
Name ____________________________________________________________________________df1: {#N/A,#N/A,FALSE,"Aging Summary";#N/A,#N/A,FALSE,"Ratio Analysis";#N/A,#N/A,FALSE,"Test 120 Day Accts";#N/A,#N/A,FALSE,"Tickmarks"}
Name ___________________________________________________________________________df1: {#N/A,#N/A,FALSE,"Aging Summary";#N/A,#N/A,FALSE,"Ratio Analysis";#N/A,#N/A,FALSE,"Test 120 Day Accts";#N/A,#N/A,FALSE,"Tickmarks"}
Name __________________________________________________________________________df1: {#N/A,#N/A,FALSE,"Aging Summary";#N/A,#N/A,FALSE,"Ratio Analysis";#N/A,#N/A,FALSE,"Test 120 Day Accts";#N/A,#N/A,FALSE,"Tickmarks"}
Name _________________________________________________________________________df1: {#N/A,#N/A,FALSE,"Aging Summary";#N/A,#N/A,FALSE,"Ratio Analysis";#N/A,#N/A,FALSE,"Test 120 Day Accts";#N/A,#N/A,FALSE,"Tickmarks"}
Name ________________________________________________________________________df1: {#N/A,#N/A,FALSE,"Aging Summary";#N/A,#N/A,FALSE,"Ratio Analysis";#N/A,#N/A,FALSE,"Test 120 Day Accts";#N/A,#N/A,FALSE,"Tickmarks"}
Name _______________________________________________________________________df1: {#N/A,#N/A,FALSE,"Aging Summary";#N/A,#N/A,FALSE,"Ratio Analysis";#N/A,#N/A,FALSE,"Test 120 Day Accts";#N/A,#N/A,FALSE,"Tickmarks"}
Name ______________________________________________________________________df1: {#N/A,#N/A,FALSE,"Aging Summary";#N/A,#N/A,FALSE,"Ratio Analysis";#N/A,#N/A,FALSE,"Test 120 Day Accts";#N/A,#N/A,FALSE,"Tickmarks"}
Name _____________________________________________________________________df1: {#N/A,#N/A,FALSE,"Aging Summary";#N/A,#N/A,FALSE,"Ratio Analysis";#N/A,#N/A,FALSE,"Test 120 Day Accts";#N/A,#N/A,FALSE,"Tickmarks"}
Name ____________________________________________________________________df1: {#N/A,#N/A,FALSE,"Aging Summary";#N/A,#N/A,FALSE,"Ratio Analysis";#N/A,#N/A,FALSE,"Test 120 Day Accts";#N/A,#N/A,FALSE,"Tickmarks"}
Name ___________________________________________________________________df1: {#N/A,#N/A,FALSE,"Aging Summary";#N/A,#N/A,FALSE,"Ratio Analysis";#N/A,#N/A,FALSE,"Test 120 Day Accts";#N/A,#N/A,FALSE,"Tickmarks"}
Name __________________________________________________________________df1: {#N/A,#N/A,FALSE,"Aging Summary";#N/A,#N/A,FALSE,"Ratio Analysis";#N/A,#N/A,FALSE,"Test 120 Day Accts";#N/A,#N/A,FALSE,"Tickmarks"}
Name _________________________________________________________________df1: {#N/A,#N/A,FALSE,"Aging Summary";#N/A,#N/A,FALSE,"Ratio Analysis";#N/A,#N/A,FALSE,"Test 120 Day Accts";#N/A,#N/A,FALSE,"Tickmarks"}
Name ________________________________________________________________df1: {#N/A,#N/A,FALSE,"Aging Summary";#N/A,#N/A,FALSE,"Ratio Analysis";#N/A,#N/A,FALSE,"Test 120 Day Accts";#N/A,#N/A,FALSE,"Tickmarks"}
Name _______________________________________________________________df1: {#N/A,#N/A,FALSE,"Aging Summary";#N/A,#N/A,FALSE,"Ratio Analysis";#N/A,#N/A,FALSE,"Test 120 Day Accts";#N/A,#N/A,FALSE,"Tickmarks"}
Name ______________________________________________________________df1: {#N/A,#N/A,FALSE,"Aging Summary";#N/A,#N/A,FALSE,"Ratio Analysis";#N/A,#N/A,FALSE,"Test 120 Day Accts";#N/A,#N/A,FALSE,"Tickmarks"}
Name _____________________________________________________________df1: {#N/A,#N/A,FALSE,"Aging Summary";#N/A,#N/A,FALSE,"Ratio Analysis";#N/A,#N/A,FALSE,"Test 120 Day Accts";#N/A,#N/A,FALSE,"Tickmarks"}
Name ____________________________________________________________df1: {#N/A,#N/A,FALSE,"Aging Summary";#N/A,#N/A,FALSE,"Ratio Analysis";#N/A,#N/A,FALSE,"Test 120 Day Accts";#N/A,#N/A,FALSE,"Tickmarks"}
Name ___________________________________________________________df1: {#N/A,#N/A,FALSE,"Aging Summary";#N/A,#N/A,FALSE,"Ratio Analysis";#N/A,#N/A,FALSE,"Test 120 Day Accts";#N/A,#N/A,FALSE,"Tickmarks"}
Name _________________________________________________________df1: {#N/A,#N/A,FALSE,"Aging Summary";#N/A,#N/A,FALSE,"Ratio Analysis";#N/A,#N/A,FALSE,"Test 120 Day Accts";#N/A,#N/A,FALSE,"Tickmarks"}
Name ________________________________________________________df1: {#N/A,#N/A,FALSE,"Aging Summary";#N/A,#N/A,FALSE,"Ratio Analysis";#N/A,#N/A,FALSE,"Test 120 Day Accts";#N/A,#N/A,FALSE,"Tickmarks"}
Name ________________________________________________________xlfn.BAHTTEXT: #NAME?
Name _______________________________________________________df1: {#N/A,#N/A,FALSE,"Aging Summary";#N/A,#N/A,FALSE,"Ratio Analysis";#N/A,#N/A,FALSE,"Test 120 Day Accts";#N/A,#N/A,FALSE,"Tickmarks"}
Name _______________________________________________________xlfn.BAHTTEXT: #NAME?
Name ______________________________________________________df1: {#N/A,#N/A,FALSE,"Aging Summary";#N/A,#N/A,FALSE,"Ratio Analysis";#N/A,#N/A,FALSE,"Test 120 Day Accts";#N/A,#N/A,FALSE,"Tickmarks"}
Name ______________________________________________________xlfn.BAHTTEXT: #NAME?
Name _____________________________________________________df1: {#N/A,#N/A,FALSE,"Aging Summary";#N/A,#N/A,FALSE,"Ratio Analysis";#N/A,#N/A,FALSE,"Test 120 Day Accts";#N/A,#N/A,FALSE,"Tickmarks"}

Sheet Executive Summary 
A1: TRUMP TOWERS
A2: INTERNAL FINISHES WORKS
A3: SUMMARY
A4: Sr. No. | B4: Description | C4: Amount | D4: Remarks
A5: A | B5: FINISHING WORK
A6: 1 | B6: FLOORING WORKS | C6: ='BOQ '!I65 -> 0
A7: 2 | B7: CLADDING WORKS | C7: ='BOQ '!I79 -> 0
A8: 3 | B8: PLASTERING | C8: ='BOQ '!I91 -> 0
A9: 4 | B9: PAINTING WORKS | C9: ='BOQ '!I116 -> 0
A10: 5 | B10: CEILING WORKS | C10: ='BOQ '!I125 -> 0
A11: 6 | B11: MISCELLENIOUS WORKS | C11: ='BOQ '!I137 -> 0
B13: TOTAL - A | C13: =SUM(C5:C12) -> 0
A14: B | B14: Tax
B15: GST 18% | C15: =C13*18% -> 0
B16: TOTAL - B | C16: =SUM(C15) -> 0
B18: NET AMOUNT = A + B | C18: =C16+C13 -> 0

Sheet PREAMBLE
A1: Riverday Infrastructure Pvt Ltd
A2: TRUMP TOWER - 69, GURGAON (HARYANA)
A3: PREAMBLE TO of BOQ for TRUMP TOWER Apartment at Sec-69
A4: SR. NO. | B4: DESCRIPTION | C4: REMARKS
B6: The rate for each item of work included in the Bill of Quantities shall, unless expressly stated otherwise, include cost of:
A7: 1 | B7: All items of work covered in this Contract shall be executed strictly as per the requirements detailed in the specifications. Entire execution shall be in total compliance with Specifications, Bill of Quantities,Technical specification, approved drawings(If any) and relevant IS Codes and as per approval of Engineer-in-Charge.
A8: =max($A$4:A7)+1 -> 2 | B8: The unit rate for all Items shall include cost of all taxes (excluding GST & labour cess) and duties and also including packing, forwarding, freight, insurance and transport to site, storage, installation, testing, commissioning,headover and profit, security of material, protection of work till handing over, cleaning, and any other expenses required to complete the works. Rates shall be for all height & levels, Location, Logistics, site HSE, labour welfare, Govt Holidays, inclemently weather, task lighting, scaffolding, tools & tackles including NGT/GRAP ban as per government notifications. This will also applicable for Free issue materials.
A9: =max($A$4:A8)+1 -> 3 | B9: All type of Wastage of materials
A10: =max($A$4:A9)+1 -> 4 | B10: All rates quoted are inclusive of cutting holes and chases in walls and floors and making good the same with adhesive, cement mortar / Gypsum Plaster/ concrete / water proofing etc all specified in drawing / design of appropriate mix and strength as directed by the Engineer-in-Charge. Contractor shall provide holes, sleeves, recesses in the concrete and masonry work as the work proceeds. Quantifying, placing of orders, all wastages, scheduling delivery sequences, taking delivery at ground level and in an area accessible by vehicles, manually, unloading, carrying in, sorting, storing, stripping or clearing off protective wrapping or covering, checking, assembling, returning packing, handling, distributing at various levels and locations, hoisting and placing or lowering in positions, fitting and fixing materials and goods in position, adjusting, refixing and for cutting away and making good, levelling, packing, grouting and pointing with approved materials, providing templates and the like, all in accordance with the generally accepted attendance requirements relating to the specific item, including safeguarding and protection of the works until the issue of the Certificate of Substantial Completion and/or till handing over to end user.
A11: =max($A$4:A10)+1 -> 5 | B11: Liabilities, obligations and risks arising out of Conditions of Contract.
A12: =max($A$4:A11)+1 -> 6 | B12: All requirements of Specifications, whether such requirements are mentioned in the item or not. The Specifications and Drawings where available are to be read as complimentary to and part of the Bill of Quantities and any work called for in one shall be taken as required for all.
A13: =max($A$4:A12)+1 -> 7 | B13: Submission of coordinated shop drawings before start of Works and further execution of works in co-ordination with other agencies as per direction of Engineer-In charge.
A14: =max($A$4:A13)+1 -> 8 | B14: Making all necessary templates, patterns moulds, platforms etc.
A15: =max($A$4:A14)+1 -> 9 | B15: Work in patches, narrow widths, curved surfaces, projected bands set backs, offsets etc.
A16: =max($A$4:A15)+1 -> 10 | B16: Providing grooves, openings, cut-outs, chases & chamfer, edge rounding etc. as per drawing and specification.
A17: =max($A$4:A16)+1 -> 11 | B17: Coordination for all items and other Vendor's Works i.e. MEP works including light fixtures, CP & Sanitary works, AC units, AC grills & Diffusers, Modular Kitchen, Kitchen Sinks, White Goods, Home Automation, Switches, Sockets, DBs, Plumbing and Fire pipelines as direction of Engineer-In charge.
A18: =max($A$4:A17)+1 -> 12 | B18: Scaffolding will be in contractors scope for all lifts and heights.
A19: =max($A$4:A18)+1 -> 13 | B19: The quantities mentioned against each item in BOQ are indicative only. Contractor to provide variation of quantity after getting formal notification to start work, The Contractor shall be paid for the actual quantity of work executed and certified by Engineer-In charge.
... A21: =max($A$4:A20)+1 -> 15 | B21: Tile size given in BOQ are tentative, this may change during execution. No additional charge shall be payable for change in size.
B23: Flooring and wall cladding Specification / Rates shall Include:
A24: =max($A$4:A23)+1 -> 16 | B24: Pre and post sealer Coat suitable for stone at all the edges and surfaces as per direction of Engineer-In charge
A25: =max($A$4:A24)+1 -> 17 | B25: Laying/fixing of Stone/Marble/Tiles etc. in any pattern, shape and sizes as per approved drawing.
A26: =max($A$4:A25)+1 -> 18 | B26: Stonework facing for drop beams of the suspended slabs will be measured same as the item of stone walls unless otherwise is specified in the Bills of Quantities.
A27: =max($A$4:A26)+1 -> 19 | B27: Thickness of stone works given refers to the nominal thickness or the approved thickness by Engineer-in-Charge. No allowance will be made for any additional thickness due to uneven or bad workmanship or to variations in the thickness of the stone
A28: =max($A$4:A27)+1 -> 20 | B28: Shaping of the apparent faces of stones as per drawings and the Instructions of the Architect
A29: =max($A$4:A28)+1 -> 21 | B29: Fabricated wire mesh, dowels, hangers and all tying and fixing tools for stone cladding works as per direction of Engineer- In-Charge
A30: =max($A$4:A29)+1 -> 22 | B30: Pointing including cleaning of stones, scaffolding and dismantling the same and all incidentals. Lintels and other reinforced concrete elements including reinforcement except those elements specified in separate items in the BOQ.
A31: =max($A$4:A30)+1 -> 23 | B31: The rate quoted shall include the cost of all the materials & consumables like Tile, Stone, Cement, Sand, White cement, Pigment, Protection of Flloring etc.
A32: =max($A$4:A31)+1 -> 24 | B32: The stone shall be fixed with mortar in position without the use of chips or under pinning of any sort of deleterious material
A33: =max($A$4:A32)+1 -> 25 | B33: The contractor will arrange verification of all stone lots at source by SDPL representative. Only after due approval , the stone will be procured / transported at site. No lot will be allowed without approval from SDPL. Any type of crack of marble to be fixed with epoxy.
B34: Plastering Works Specification / Methodology / Rates shall Include:
A35: =max($A$4:A34)+1 -> 26 | B35: Gypsum Plaster should pass Standard Compliance IS 2547 (Part I)-1976 for chemical characteristics and IS 2547 (Part II)-1976 for physical characteristics.
A36: =max($A$4:A35)+1 -> 27 | B36: Gypsum plaster should meet technical & physical Parameters like Dry Bulk Density 770 Kg/m3 (Max), Wet Bulk Density 1.35-1.5 g/cm3, Water To Powder Ratio 1:1.25 and thermal resistance R = 0.07m²K/W or as approved by Engineer-in-Charge.
A37: =max($A$4:A36)+1 -> 28 | B37: Junction between straight, raking and curved work are in all cases included with the work in which they occur.
A38: =max($A$4:A37)+1 -> 29 | B38: Certain items are referenced directly to detail drawings to eliminate detailed description. All such reference includes all work to execute the detail.
B40: Carpentry Wood Works Specification / Methodology / Rates shall Include:
A41: =max($A$4:A40)+1 -> 30 | B41: Sizes of timber given in the Bills of Quantities are finished sizes and shall be as per Drawings
A42: =max($A$4:A41)+1 -> 31 | B42: Sizes of doors and other items mentioned in the Bills of Quantities shall allow for tolerance to suit the structural openings as per drawings.
A43: =max($A$4:A42)+1 -> 32 | B43: Work shall include for: Labor, Shop drawings, Any length of timber / board, Joints in the running length of timber / board / Veneer, Raking, curved or circular work and labors, Frames, architrave, chalk holders and other holders and kick plates etc, Allowance for plastering and tiling and the like, Forming holes, angles, ends, miters, rebates, splayed edges, grooves, chamfers, scribed edges, rounded edges, rounded corners, notches, sinkings, fitted ends, far ends and the like, Cutting and fitting around obstructions, Forming moldings, Nosing, bed moulds, margins, and the like, Facing and edging to board / Veneer, Bedding and painting in PU polish as specified, )Grounds, blockings and backings, Plugging concrete, blockwork, and stonework, and making good, installation of all types of ironmongery including cylindrical locks, handles, stoppers, screws, temporarily fixing, re-fixing, oiling and adjusting etc as specified, hardware including nails, screws, dowels, cramps and the like, Steel legs, brackets, bearers and other supports including painting, Glass and glazing including cutting to size and putty, Preparing surfaces to receive finishes, PU Painting // Polishing and the like, to any area or width in any location including work in multicolour and cutting in edges.
A44: =max($A$4:A43)+1 -> 33 | B44: Cost for wooden Flooring to be included with all accessories, edge profiles, skirting etc complete as per drawing, design and specification.
...

Sheet BOQ 
A1: PROJECT: TRUMP TOWERS BILL OF QUANTITIES - FINISHING WORKS
A2: ESTIMATED BILL OF QUANTITIES
A3: Sl.No | B3: Description | C3: UNIT | D3: Basement | E3: T-01 | F3: T-02 | G3: Total Qty | H3: Rate (in Rs) | I3: Amount (in Rs)
A5: A | B5: FLOORING WORKS
A7: 1 | B7: Imported Marble
B8: Providing, stacking, cutting, laying and fixing Imported Marble of approved quality, shade, colour, design, texture and pattern in flooring laid on average 30mm thick cement mortar 1:4 (1 cement : 4 coarse sand) with white cement slury to match the final finished level, joint to be filled with white cement mixed with pigment to match the shade of stone including cutting of stone, surfaces pointing, rubbing, grinding, buffing, Diamond Polishing, approved sealer, curing, protection with 6mm polypropylene sheet until the handing over, making provision for MEP work wherever required, grooves, rebates, reveals, stain & scratch resistance, , for all lead & lift, complete as per specification and drawing up to the satisfaction of Engineer In-Charge.
A9: a | B9: Minimum 18mm thick Imported Marble @ Base Rate FOR at site INR 350/Sft | C9: Sqm | E9: 22331.959 | F9: 22331.959 | G9: =SUM(D9:F9) -> 44663.918 | I9: =G9*H9 -> 0
A11: 2 | B11: Providing, stacking, cutting, laying and fixing Imported Marble of approved quality, shade, colour, design, texture and pattern in skirting over average 12 mm thick cement mortar 1:3 (1 Cement : 3 Coarse Sand) to match the total thickness of wall finish and jointed with cement slurry including Grouting and pointing with white cement paste with pigmented additives matching the shade of the stone. The rate should also be inclusive of surface preparation, cuttng, unloading, shifting to respective floors, hand buffing / cleaning, Diamond Polishing on surface, approved sealer, edge chamfering etc for all lead & lift complete as per directions of Client.
A12: a | B12: Minimum 18mm thick Imported Marble, 75mm high @ Base Rate FOR at site INR 350/Sft | C12: Rmt | E12: 17747.5 | F12: 17747.5 | G12: =SUM(D12:F12) -> 35495 | I12: =G12*H12 -> 0
A14: 3 | B14: Engineered wooden flooring & skirting
B15: Providing and fixing Engineered wooden flooring 14 mm thick , as per approved sample, make, over 5mm thick underlayer polyurethene foam on polythene sheet 250 micron (or as per manufacturer Specification), over a smooth, flat, hard subfloor free from moisture, grease, protection with 6mm polypropylene sheet until the handing over, etc. complete in all respect with requisite accessories like end profile, transition profile, reducer profile, item to be inclusive of cost of 75mm high Engineered Wooden Skirting, including reducer profile, lipping etc, epoxy filling all around of flooring etc. wherever required and preparation of base including all other incidental works for all lead & lift. Quoted rates must include the Engineered wooden flooring accessories. complete as per specification and drawing up to the satisfaction of Engineer In-Charge. (Only plan area to be measured and paid ).
A16: a | B16: Basic rate of material (including Wooden flooring, all required accessories, profiles, skirting, etc.)- INR 250/Sft | C16: Sqm | E16: 11650 | F16: 11650 | G16: =SUM(D16:F16) -> 23300 | I16: =G16*H16 -> 0
A18: 4 | B18: Vitrified Tile
B19: Providing, cutting, laying and fixing Vitrified Tile flooring of approved size, shade & make as approved by Architect laid over average 30mm thick bed of cement mortar 1:4 (1 cement : 4 coarse sand) to match with floor finish level with grey cement slurry, filling the joints with white cement using pigment to match the shade of tile as required, protection with 6mm polypropylene sheet until the handing over, cutting for trap in floor tiles laid as per design, pattern & drawing approved by Architect for various thickness of tiles and for all lead & lift complete up to the satisfaction of Engineer In-Charge.
A20: a | B20: 600x600mm, Matt Finish, Vitrified Tile @ Base Rate FOR at site INR 40/Sft | C20: Sqm | E20: 1470 | F20: 1470 | G20: =SUM(D20:F20) -> 2940 | I20: =G20*H20 -> 0
A21: b | B21: 600x600mm, Vitrified Tile flooring @ Base Rate FOR at site INR 40/Sft | C21: Sqm | D21: 475 | G21: =SUM(D21:F21) -> 475 | I21: =G21*H21 -> 0
A23: =A18+1 -> 5 | B23: Providing, cutting, laying and fixing Vitrified Tile 75mm high skirting of approved size, shade & make as approved by Architect with average 12mm thick cement mortar 1:3 (1 cement : 3 coarse sand) to match with wall finish level with grey cement slurry, filling the joints with white cement using pigment to match the shade of tile as required, for all lead & lift, as per design, pattern & drawing approved by Architect for various thickness of tiles and complete up to the satisfaction of Engineer In-Charge.
A24: a | B24: 600x600mm, Matt Finish, Vitrified Tile @ Base Rate FOR at site INR 40/Sft | C24: Rmt | E24: 2100 | F24: 2100 | G24: =SUM(D24:F24) -> 4200 | I24: =G24*H24 -> 0
A25: b | B25: 600x600mm, Vitrified Tile @ Base Rate FOR at site INR 40/Sft | C25: Rmt | G25: =SUM(D25:F25) -> 0 | I25: =G25*H25 -> 0
A27: 6 | B27: Vitrified Tile
B28: 'Providing, cutting, laying and fixing Vitrified Tile flooring of approved make, size, shade & make as approved by Architect laid over average 30mm thick to match with floor finish level bed of cement mortar 1:4 (1 cement : 4 coarse sand) with grey cement slurry, filling the joints with epoxy grout using pigment to match the shade of tile as required, including 3mm spacer, protection with 6mm polypropylene sheet until the handing over, cutting for floor trap in tiles laid as per design, pattern & drawing approved by Architect for various thick of tiles, for all lead & lift, complete up to the satisfaction of Engineer In-Charge.
A29: a | B29: 285x1800mm, Matt Finish, Vitrified Tile flooring @ Base Rate FOR at site INR 50/Sft | C29: Sqm | E29: 6405 | F29: 6405 | G29: =SUM(D29:F29) -> 12810 | I29: =G29*H29 -> 0
A30: b | B30: 285x1800mm, Matt Finish, Vitrified Tile flooring @ Base Rate FOR at site INR 50/Sft | C30: Sqm | E30: 920 | F30: 920 | G30: =SUM(D30:F30) -> 1840 | I30: =G30*H30 -> 0
A32: 7 | B32: Providing, cutting, laying and fixing Vitrified Tile 75mm high skirting of approved size, shade & make as approved by Architect with average 12mm thick bed of cement mortar 1:3 (1 cement : 3 coarse sand) to match with wall finish level with grey cement slurry, filling the joints with epoxy grout using pigment to match the shade of tile as required, including 3mm spacer, protection with 6mm polypropylene sheet until the handing over, for all lead & lift, as per design, pattern & drawing approved by Architect for various thickness of tiles and complete up to the satisfaction of Engineer In-Charge.
A33: a | B33: 285x1800mm, Matt Finish, Premium Vitrified Tile @ Base Rate FOR at site INR 50/Sft | C33: Rmt | E33: 3840 | F33: 3840 | G33: =SUM(D33:F33) -> 7680 | I33: =G33*H33 -> 0 | K33: 144 | L33: =(H33+H34)/2 -> 0
A34: b | B34: 285x1800mm, Matt Finish, Vitrified Tile @ Base Rate FOR at site INR 50/Sft | C34: Rmt | E34: 1360 | F34: 1360 | G34: =SUM(D34:F34) -> 2720 | I34: =G34*H34 -> 0 | K34: 122
A36: 8 | B36: Staircase Flooring
B37: Providing, cutting and laying full body vitrified Tile specially designed for stair case in specified size, pattern as per design/drawings and specification laid over average 30mm thick cement mortar 1:3 (1 cement : 3 coarse sand) to match the total thickness of floor finish, jointed with cement mixed with pigment to match the shade of tile, making holes if any required complete, as per specification, drawing & direction of Project Manager.
A38: a | B38: Tread & Landing
B39: 300X1250mm Tile @ Base Rate FOR at site INR 80/Sft Note:- Size of tile may vary for landing | C39: Sqm | D39: 1570 | E39: 2611 | F39: 2611 | G39: =SUM(D39:F39) -> 6792 | I39: =G39*H39 -> 0
A41: b | B41: Risers
B42: Item same above but with 12mm thick cement mortar instead of 30mm mortar, '150x1250mm Tile @ Base Rate FOR at site INR 80/Sft | C42: Sqm | D42: 105 | E42: 1286 | F42: 1286 | G42: =SUM(D42:F42) -> 2677 | I42: =G42*H42 -> 0
A44: c | B44: Staircase Skirting 75mm high
B45: Item same as item.no.8 but with 12mm thick cement mortar instead of 30mm mortar, Tile @ Base Rate FOR at site INR 80/Sft | C45: Rmt | D45: 735 | E45: 1647 | F45: 1647 | G45: =SUM(D45:F45) -> 4029 | I45: =G45*H45 -> 0
A47: 9 | B47: Granite Coping
B48: Providing, cutting, laying and fixing minimum 18mm thick prepolished granite stone finish of approved size, shade & make as approved by Architect laid over average 30mm thick bed of cement mortar 1:4 (1 cement : 4 coarse sand) to match with floor finish level with grey cement slurry, filling the joints with white cement using pigment to match the shade of Granite as required including rubbing, buffing, Chamfer, edge polishing, rounding, pattern as per drawing approved by Architect, for all lead & lift complete up to the satisfaction of Engineer In-Charge.
A49: a | B49: Coping to balcony upstands 175mm wide @ Base Rate FOR at site INR 200/Sft | C49: Rmt | E49: 9367 | F49: 9367 | G49: =SUM(D49:F49) -> 18734 | I49: =G49*H49 -> 0
A50: b | B50: Providing, cutting, laying and fixing 18mm thick granite stone finish of approved size, shade & make as approved by Architect laid over 30mm thickness to match with floor finish level bed of cement mortar 1:4 (1 cement : 4 coarse sand) with grey cement slurry, filling the joints with white cement using pigment to match the shade of Granite as required, cutting for trap in floor granite laid as per design, pattern & drawing approved by Architect for various thickness of granite and complete up to the satisfaction of Engineer In-Charge.
B51: Flooring @ Base Rate FOR at site INR 200/Sft | C51: Sqm | E51: 2500 | F51: 2500 | G51: =SUM(D51:F51) -> 5000 | I51: =G51*H51 -> 0
A53: =A47+1 -> 10 | B53: Heat Reflective tiles
...
